<?xml version="1.0"?>
<robot xmlns:xacro="http://www.ros.org/wiki/xacro">

    <xacro:include filename="inertial_macros.xacro"/>

    <link name="world"/>

    <joint name="base_joint" type="fixed">
        <parent link="world"/>
        <child link="base_link"/>
        <origin xyz="0.0 0.0 0.0" rpy="0.0 0.0 0.0"/>
    </joint>

    <link name="base_link">
        <visual>
            <origin xyz="0.0 0.125 0.25" rpy="0.0 0.0 0.0"/>
            <geometry>
                <box size="0.25 0.125 0.5"/>
            </geometry>
            <material name="white">
                <color rgba="1.0 1.0 1.0 1.0"/>
            </material>
        </visual>
        <collision>
            <origin xyz="0.0 0.5 0.25" rpy="0.0 0.0 0.0"/>
            <geometry>
                <box size="0.25 0.125 0.5"/>
            </geometry>
        </collision>
        <xacro:inertial_box mass="0.05" x="0.25" y="0.125" z="0.5">
            <origin xyz="0.0 0.25 0.25" rpy="0.0 0.0 0.0"/>
        </xacro:inertial_box>
    </link>

    <link name="motor_link">
        <visual>
            <origin xyz="0.125 0.0 0.0625" rpy="0.0 0.0 0.0"/>
            <geometry>
                <box size="0.25 0.125 0.125"/>
            </geometry>
            <material name="red">
                <color rgba="1.0 0.0 0.0 1.0"/>
            </material>
        </visual>
        <collision>
            <origin xyz="0.125 0.0 0.0625" rpy="0.0 0.0 0.0"/>
            <geometry>
                <box size="0.25 0.125 0.125"/>
            </geometry>
        </collision>
        <xacro:inertial_box mass="0.02" x="0.25" y="0.125" z="0.125">
            <origin xyz="0.125 0.0 0.0625" rpy="0.0 0.0 0.0"/>
        </xacro:inertial_box>
    </link>

    <joint name="motor_to_base_joint" type="fixed">
        <parent link="base_link"/>
        <child link="motor_link"/>
        <origin xyz="0.0 0.0 0.5" rpy="0.0 0.0 1.57"/>
    </joint>

    <link name="lidar_base_link">
        <visual>
            <origin xyz="0.0625 0.0 0.0" rpy="0.0 0.0 0.0"/>
            <geometry>
                <box size="0.125 0.125 0.05"/>
            </geometry>
            <material name="green">
                <color rgba="0.0 1.0 0.0 1.0"/>
            </material>
        </visual>
        <collision>
            <origin xyz="0.0625 0.0 0.0" rpy="0.0 0.0 0.0"/>
            <geometry>
                <box size="0.125 0.125 0.05"/>
            </geometry>
        </collision>
        <xacro:inertial_box mass="0.01" x="0.125" y="0.125" z="0.05">
            <origin xyz="0.0625 0.0 0.0" rpy="0.0 0.0 0.0"/>
        </xacro:inertial_box>
    </link>

    <joint name="lidar_base_to_motor_joint" type="revolute">
        <axis xyz="1.0 0.0 0.0"/>
        <limit lower="-1.57" upper="1.57" effort="1000.0" velocity="0.5"/>
        <origin xyz="0.25 0.0 0.125" rpy="0.0 0.0 0.0"/>
        <parent link="motor_link"/>
        <child link="lidar_base_link"/>
    </joint>

    <link name="lidar_sensor_link">
        <visual>
            <origin xyz="0.0 0.0 0.0" rpy="0.0 0.0 0.0"/>
            <geometry>
                <cylinder radius="0.05" length="0.05"/>
            </geometry>
            <material name="blue">
                <color rgba="0.0 0.0 1.0 1.0"/>
            </material>
        </visual>
        <collision>
            <origin xyz="0.0 0.0 0.0" rpy="0.0 0.0 0.0"/>
            <geometry>
                <cylinder radius="0.05" length="0.05"/>
            </geometry>
            <material name="blue">
                <color rgba="0.0 0.0 1.0 1.0"/>
            </material>
        </collision>
        <xacro:inertial_cylinder mass="0.01" length="0.05" radius="0.05">
            <origin xyz="0.0 0.0 0.0" rpy="0.0 0.0 0.0"/>
        </xacro:inertial_cylinder>
    </link>

    <joint name="lidar_sensor_to_base_joint" type="fixed">
        <parent link="lidar_base_link"/>
        <child link="lidar_sensor_link"/>
        <origin xyz="0.0625 0.0 0.05" rpy="0.0 0.0 0.0"/>
    </joint>
    
    <gazebo>
        <plugin name="gazebo_ros_control" filename="libgazebo_ros_control.so">
        <robotNamespace>/my_robot</robotNamespace>
        </plugin>
    </gazebo>

    <transmission name="motor_to_lidar_base">
        <type>transmission_interface/SimpleTranmission</type>
        <actuator name="motor 1">
        <mechanicalReduction>1</mechanicalReduction>
        </actuator>
        <joint name="lidar_base_to_motor_joint">
            <hardwareInterface>hardware_interface/PositionJointInterface</hardwareInterface>
        </joint>
    </transmission>

</robot>